{"name": "test_answer", "status": "failed", "statusDetails": {"message": "AssertionError: assert 4 == 5\n +  where 4 = func(3)", "trace": "def test_answer():\n>       assert func(3) == 5\nE       assert 4 == 5\nE        +  where 4 = func(3)\n\nrun_demo\\test1\\test_funcname.py:10: AssertionError"}, "start": 1638955469625, "stop": 1638955469625, "uuid": "3bc64d1e-1216-451e-81b3-924d847198e8", "historyId": "013a40e1d1e1431bc6e9780f62a96c4a", "testCaseId": "884dab4826ec718858e72339ddaeb9a3", "fullName": "run_demo.test1.test_funcname#test_answer", "labels": [{"name": "parentSuite", "value": "run_demo.test1"}, {"name": "suite", "value": "test_funcname"}, {"name": "host", "value": "ZB-PF1BEK8Z"}, {"name": "thread", "value": "18984-MainThread"}, {"name": "framework", "value": "pytest"}, {"name": "language", "value": "cpython3"}, {"name": "package", "value": "run_demo.test1.test_funcname"}]}